Workbook

Sheet Read Me
A1: Appropriations Pilot — CJS Title III (Science) + Labor-HHS Title II (HHS), Loaded Against the Schema
A2: Built from your filled-in CJS_Title_III_Science_Pilot_Schema_Loaded workbook. Five tabs, matching the Data Dictionary in the scoping doc.
A4: v37: verified links; how each year was enacted
A5: • Links: 45 links (source documents and Bill Report Reference bill_url / report_jes_url) now point at the file whose sha256 matches the document we ingested (Claude Code link check, link_results_v36.csv). Older reports (FY2017–FY2023) use govinfo, since Congress.gov serves a re-stamped copy; 118th–119th reports use Congress.gov. The 12 Labor-HHS bill_url landing pages are now PDFs. The FY2023 Senate Labor-HHS statement uses its direct PDF. Links that could not be checked (no stored file) are unchanged. The build now also stops on a landing-page bill_url.
A6: • Bill Report Reference: four new columns on Enacted rows: vehicle_bill_id (the bill the law was enacted as), division, enactment_date and funding_type (standalone / minibus / omnibus / full_year_cr). Values for the 14 enacted rows are from the National Taxpayers Union Foundation's Definitive Congressional Appropriations History Database; every public law matched our bill_id. FY2025 (CJS and Labor-HHS) is full_year_cr (P.L. 119-4).
A7: • Page check: 140 of the cited figures were not found by text search on their cited page; nearly all are on image pages (OCR), and no document shows a consistent page offset, so no page was changed. They are listed in the repo (page_check_misses_v36.csv) for review. No figure, page or ID changed.
A9: v36: link corrections
A10: • H.Rpt. 118-585: govinfo files this report as CRPT-118hrpt585-pt1, so the v35 package URL returned a web page, not the PDF. It now links the Congress.gov PDF, whose sha256 matches the ingested file. The eight Bill Report Reference report_jes_url values that were still govinfo landing pages now carry the same PDF links as their Source Documents. The build now stops on any govinfo landing-page link in either place. No figure, page or ID changed.
A12: v35: source links open the PDF
A13: • Nine govinfo sources were stored as their landing pages (govinfo.gov/app/details/...), which cannot open at a page. They now point to the PDF itself (govinfo.gov/content/pkg/<package>/pdf/<file>.pdf): S.Rpt. 118-84, 118-207, 119-55; H.Rpt. 118-585, 119-271, 119-696, 117-403; the FY2026 Labor-HHS explanatory statement (Congressional Record, 2026-01-22); P.L. 119-4. No figure, page or ID changed.
A15: v34: verification rule enforced, AHA relationships
A16: • One rule now sets verification_status everywhere: 'auto-validated' only with confidence >= 0.90, every check passing, and at least one check that confirms the figure (a sum or cross-document match); 'flagged' when a check fails or a person deliberately flagged it; otherwise 'unverified'. 382 Labor-HHS rows moved from auto-validated to unverified, 2 the other way. No auto-validated row is below 0.90.
... A65: • Your 9 already-filled Bill Report Reference rows carried forward untouched, just with subcommittee = CJS added and their reference_id/lookup_key updated to match.

Sheet Account
A1: canonical_account_id | B1: canonical_name | C1: agency | D1: bureau | E1: treasury_account_symbol | F1: status | G1: historical_names | H1: historical_identifiers | I1: fund_type | J1: subcommittee | K1: notes | L1: title | M1: display_order | N1: total_scope | O1: parent_account_id
A2: ACC-OSTP | B2: Office of Science and Technology Policy | C2: Executive Office of the President | D2: Office of Science and Technology Policy | F2: active | I2: general | J2: CJS | L2: Title III | M2: 1
A3: ACC-NSC | B3: National Space Council | C3: Executive Office of the President | D3: National Space Council | F3: active | I3: general | J3: CJS | L3: Title III | M3: 2
A4: ACC-NASA-TOTAL | B4: National Aeronautics and Space Administration (agency total) | C4: National Aeronautics and Space Administration | D4: (Agency Total) | F4: active | I4: general | J4: CJS | K4: Derived rollup — equals the sum of NASA's 9 program accounts below; kept as a reference row, not an independent funding decision. | L4: Title III | M4: 12 | N4: agency
A5: ACC-NASA-SCIENCE | B5: Science | C5: National Aeronautics and Space Administration | D5: Science Mission Directorate | F5: active | I5: general | J5: CJS | L5: Title III | M5: 3
A6: ACC-NASA-AERONAUTICS | B6: Aeronautics | C6: National Aeronautics and Space Administration | D6: Aeronautics Research Mission Directorate | F6: active | I6: general | J6: CJS | L6: Title III | M6: 4
A7: ACC-NASA-SPACETECH | B7: Space Technology | C7: National Aeronautics and Space Administration | D7: Space Technology Mission Directorate | F7: active | G7: Exploration Research and Technology; Exploration Technology | I7: general | J7: CJS | L7: Title III | M7: 5
A8: ACC-NASA-EXPLORATION | B8: Exploration | C8: National Aeronautics and Space Administration | D8: Exploration Systems Development | F8: active | G8: Deep Space Exploration Systems | I8: general | J8: CJS | L8: Title III | M8: 6
A9: ACC-NASA-SPACEOPS | B9: Space Operations | C9: National Aeronautics and Space Administration | D9: Space Operations Mission Directorate | F9: active | G9: LEO and Spaceflight Operations | I9: general | J9: CJS | L9: Title III | M9: 7
A10: ACC-NASA-STEM-ENGAGEMENT | B10: Science, Technology, Engineering, and Mathematics Engagement | C10: National Aeronautics and Space Administration | D10: STEM Engagement | F10: active | G10: Education; STEM Opportunities formerly Education | I10: general | J10: CJS | L10: Title III | M10: 8
A11: ACC-NASA-SAFETY-SECURITY | B11: Safety, Security and Mission Services | C11: National Aeronautics and Space Administration | D11: Mission Support Directorate | F11: active | I11: general | J11: CJS | L11: Title III | M11: 9
A12: ACC-NASA-CONSTRUCTION | B12: Construction and Environmental Compliance and Restoration | C12: National Aeronautics and Space Administration | D12: Mission Support Directorate | F12: active | I12: general | J12: CJS | L12: Title III | M12: 10
A13: ACC-NASA-OIG | B13: Office of Inspector General | C13: National Aeronautics and Space Administration | D13: Office of Inspector General | F13: active | I13: general | J13: CJS | L13: Title III | M13: 11
A14: ACC-NSF-TOTAL | B14: National Science Foundation (agency total) | C14: National Science Foundation | D14: (Agency Total) | F14: active | I14: general | J14: CJS | K14: Derived rollup — equals the sum of NSF's 6 program accounts below; kept as a reference row, not an independent funding decision. | L14: Title III | M14: 19 | N14: agency
A15: ACC-NSF-RRA | B15: Research and Related Activities | C15: National Science Foundation | D15: Research and Related Activities | F15: active | I15: general | J15: CJS | L15: Title III | M15: 13
A16: ACC-NSF-MREFC | B16: Major Research Equipment and Facilities Construction | C16: National Science Foundation | D16: Major Research Equipment and Facilities Construction | F16: active | I16: general | J16: CJS | L16: Title III | M16: 14
A17: ACC-NSF-STEM-EDUCATION | B17: STEM Education | C17: National Science Foundation | D17: STEM Education | F17: active | G17: Education and Human Resources | I17: general | J17: CJS | L17: Title III | M17: 15
A18: ACC-NSF-AGENCY-OPS | B18: Agency Operations and Award Management | C18: National Science Foundation | D18: Agency Operations and Award Management | F18: active | I18: general | J18: CJS | L18: Title III | M18: 16
A19: ACC-NSF-NSB | B19: Office of the National Science Board | C19: National Science Foundation | D19: National Science Board | F19: active | I19: general | J19: CJS | L19: Title III | M19: 17
A20: ACC-NSF-OIG | B20: Office of Inspector General | C20: National Science Foundation | D20: Office of Inspector General | F20: active | I20: general | J20: CJS | L20: Title III | M20: 18
A21: ACC-DOJ-CVF | B21: Crime Victims Fund | C21: Department of Justice | D21: State, Local, and Tribal Justice Assistance | F21: active | I21: trust | J21: CJS | K21: Appears across multiple bill titles as a transfer-out source (to OVW, to OIG) and carries the FY27 CHIMP / CHIMP Pop-Up mandatory-program adjustment.
A22: ACC-DOJ-AFF | B22: Assets Forfeiture Fund | C22: Department of Justice | D22: Legal Activities and U.S. Marshals | F22: active | I22: trust | J22: CJS | L22: Title II | M22: 23
A23: ACC-DOJ-WCF | B23: Working Capital Fund | C23: Department of Justice | D23: Justice Operations, Management, and Accountability | F23: active | I23: working_capital | J23: CJS | K23: Subject to a Sec. 521(c)(1) rescission in the FY2027 bill. Title placement (Title V) is tentative -- derived only from a transfer or rescission line, not the account's own budget-authority line. A general provision can touch an account whose own appropriation sits in a different title. | L23: Title V | M23: 27
A24: ACC-USPTO-SE | B24: Salaries and Expenses | C24: Department of Commerce | D24: U.S. Patent and Trademark Office | F24: active | I24: general | J24: CJS | K24: Fully fee-funded: gross spending is offset almost entirely by fee collections. | L24: Title I | M24: 21
A25: ACC-DOJ-ANTITRUST-SE | B25: Salaries and Expenses, Antitrust Division | C25: Department of Justice | D25: Legal Activities and U.S. Marshals | F25: active | I25: general | J25: CJS | K25: Offset by Hart-Scott-Rodino fee collections, netting to $0 in FY2027 House Reported. | L25: Title II | M25: 24
A26: ACC-DOJ-USTSF | B26: United States Trustee System Fund | C26: Department of Justice | D26: Legal Activities and U.S. Marshals | F26: active | I26: general | J26: CJS | K26: Offsetting fee collections exceed the account's own direct appropriation. | L26: Title II | M26: 25
A27: ACC-NOAA-ORF | B27: Operations, Research, and Facilities | C27: Department of Commerce | D27: National Oceanic and Atmospheric Administration | F27: active | I27: general | J27: CJS | K27: Receives a transfer from the Promote and Develop Fisheries account; also carries a Sec. 521(a)(1) rescission in FY2027. | L27: Title I | M27: 20
A28: ACC-NOAA-PDF | B28: Promote and Develop Fishery Products and Research | C28: Department of Commerce | D28: National Oceanic and Atmospheric Administration | F28: active | I28: general | J28: CJS | K28: Transfers its full balance to Operations, Research, and Facilities every year in this series. Title placement (Title I) is tentative -- derived only from a transfer or rescission line, not the account's own budget-authority line. A general provision can touch an account whose own appropriation sits in a different title. | L28: Title I | M28: 22
A29: ACC-DOJ-OJP-RESC | B29: Office of Justice Programs Rescission | C29: Department of Justice | D29: State, Local, and Tribal Justice Assistance | F29: active | I29: general | J29: CJS | K29: A rescission-only line (Sec. 521(b)(2)), not a standing program account. Title placement (Title V) is tentative -- derived only from a transfer or rescission line, not the account's own budget-authority line. A general provision can touch an account whose own appropriation sits in a different title. | L29: Title V | M29: 28
A30: ACC-DOJ-VAWA | B30: Violence Against Women Prevention and Prosecution Programs | C30: Department of Justice | D30: State, Local, and Tribal Justice Assistance | F30: active | I30: general | J30: CJS | K30: Receives a transfer from the Crime Victims Fund. Title placement (Title II) is tentative -- derived only from a transfer or rescission line, not the account's own budget-authority line. A general provision can touch an account whose own appropriation sits in a different title. | L30: Title II | M30: 26
A31: ACC-DOJ-OIG | B31: Office of Inspector General | C31: Department of Justice | D31: Justice Operations, Management, and Accountability | F31: active | I31: general | J31: CJS | K31: Receives a transfer from the Crime Victims Fund. Title placement (Title V) is tentative -- derived only from a transfer or rescission line, not the account's own budget-authority line. A general provision can touch an account whose own appropriation sits in a different title. | L31: Title V | M31: 29
A32: ACC-HHS-AHA-TOTAL | B32: Administration for a Healthy America (agency total) | C32: Administration for a Healthy America | D32: (Agency Total) | F32: proposed | I32: general | J32: LHHS | K32: Proposed in the FY2026 and FY2027 budget requests only; never reported by a committee or enacted (P.L. 119-75 has no such heading). The committee tables print it only in the request column, as the request's funding 'not displayed under other HHS accounts below' (H.Rept. 119-271 p.334 footnote 1/): the tables show most of the proposed AHA under HRSA, SAMHSA and the other legacy lines. Derived rollup (agency). H.Rept. 119-696 prints no plain total, only 'Administration for a Healthy America, Discretionary 1/', recorded as the headline there. | L32: Title II | M32: 1 | N32: agency
A33: ACC-HHS-HRSA-HEALTH-CENTERS | B33: Health Centers | C33: Health Resources and Services Administration | D33: Primary Health Care | F33: active | I33: general | J33: LHHS | K33: A program line under Primary Health Care (with Free Clinics Medical Malpractice). | L33: Title II | M33: 2 | O33: ACC-HHS-HRSA-PRIMARY-CARE
A34: ACC-HHS-HRSA-PRIMARY-CARE | B34: Primary Health Care | C34: Health Resources and Services Administration | D34: Primary Health Care | F34: active | I34: general | J34: LHHS | K34: The appropriation heading 'Primary Health Care' (the law's dollar figure); printed as 'Total, Primary Health Care'. | L34: Title II | M34: 3
A35: ACC-HHS-HRSA-VICTF | B35: Vaccine Injury Compensation Program Trust Fund | C35: Health Resources and Services Administration | D35: Vaccine Injury Compensation Program | F35: active | I35: trust | J35: LHHS | K35: Trust fund, mandatory. The law appropriates 'such sums as may be necessary' for claims plus a fixed HRSA administrative-expenses amount (15,200); the tables' claims figure is an estimate, not a law figure. | L35: Title II | M35: 4
A36: ACC-HHS-HRSA-TOTAL | B36: Health Resources and Services Administration (agency total) | C36: Health Resources and Services Administration | D36: (Agency Total) | F36: active | I36: general | J36: LHHS | K36: Derived rollup -- HRSA's agency total as the Title II table prints it; kept as a reference row, not an independent funding decision. Includes the Vaccine Injury Compensation trust fund and the Covered Countermeasures Process Fund; 'Total, Health Resources and Services' (no 'Administration') is a smaller subtotal. | L36: Title II | M36: 5 | N36: agency
A37: ACC-HHS-CDC-TOTAL | B37: Centers for Disease Control and Prevention (agency total) | C37: Centers for Disease Control and Prevention | D37: (Agency Total) | F37: active | I37: general | J37: LHHS | K37: Derived rollup -- CDC's agency total as the Title II table prints it; kept as a reference row, not an independent funding decision. | L37: Title II | M37: 6 | N37: agency
A38: ACC-HHS-NIH-NCI | B38: National Cancer Institute | C38: National Institutes of Health | D38: National Cancer Institute | F38: active | I38: general | J38: LHHS | L38: Title II | M38: 7
A39: ACC-HHS-NIH-TOTAL | B39: National Institutes of Health (agency total) | C39: National Institutes of Health | D39: (Agency Total) | F39: active | I39: general | J39: LHHS | K39: Derived rollup (agency) -- NIH's agency total as the Title II table prints it: 'Total, National Institutes of Health (with CURES Act funding)' (decision 2026-09-27); kept as a reference row, not an independent funding decision. Since v33 the CURES Act money is its own account (ACC-HHS-NIH-CURES), one of the NIH accounts this total adds up; the Title II total subtracts the CURES line (inside NIH's total, outside the title's). | L39: Title II | M39: 8 | N39: agency
A40: ACC-HHS-SAMHSA-TOTAL | B40: Substance Abuse and Mental Health Services Administration (agency total) | C40: Substance Abuse and Mental Health Services Administration | D40: (Agency Total) | F40: active | I40: general | J40: LHHS | K40: Derived rollup -- SAMHSA's agency total as the Title II table prints it; kept as a reference row, not an independent funding decision. | L40: Title II | M40: 9 | N40: agency
...

Sheet Historical Name
A1: historical_name_id | B1: canonical_account_id | C1: former_name | D1: evidence | E1: approved_date | F1: confidence | G1: human_reviewed
A2: HN-0001 | B2: ACC-NASA-EXPLORATION | C2: Deep Space Exploration Systems | D2: Printed for this account in S.Rept. 118-62 (FY2024 Senate Reported) p.219 and the FY2024 CJS conference JES Title III table; the pilot records those FY2024 figures under ACC-NASA-EXPLORATION. Also printed as the Budget Estimate column label (not the chamber's own recommendation) in H.Rept. 115-704 p.128 (FY2019), S.Rept. 115-275 p.157 (FY2019), H.Rept. 116-101 p.148 (FY2020), S.Rept. 116-127 p.191 (FY2020), and S.Rept. 118-198 p.227 (which also prints the '(emergency)' line). | E2: 2026-09-25 | F2: 1 | G2: TRUE
A3: HN-0002 | B3: ACC-NSF-STEM-EDUCATION | C3: Education and Human Resources | D3: Printed for this account in S.Rept. 118-62 (FY2024 Senate Reported) p.220 and the FY2024 CJS conference JES Title III table; the pilot records those FY2024 figures under ACC-NSF-STEM-EDUCATION. | E3: 2026-09-25 | F3: 1 | G3: TRUE
A4: HN-0003 | B4: ACC-NASA-SPACEOPS | C4: LEO and Spaceflight Operations | D4: Printed in place of 'Space Operations' in H.Rept. 115-704 p.128 (FY2019 House Reported and President's Budget columns) and, in the Budget Estimate column only (never as the chamber's own recommendation), in S.Rept. 115-275 p.157 (FY2019) and S.Rept. 116-127 p.191 (FY2020, alongside H.Rept. 116-101 p.148). Never adopted as any chamber's own committee recommendation or in Enacted. | E4: 2026-09-25 | F4: 1 | G4: TRUE
A5: HN-0005 | B5: ACC-NASA-STEM-ENGAGEMENT | C5: Education | D5: The account's own name through FY2018, not a FY2019 variant. Printed in S.Rept. 114-239 p.139 (FY2017), S.Rept. 115-139 p.140 (FY2018), H.Rept. 115-231 p.121 (FY2018: 100,000 / 37,300 / 90,000), and H.Rept. 115-704 p.128 (FY2019 table's prior-year-enacted column: 100,000). | E5: 2026-09-25 | F5: 1 | G5: TRUE
A6: HN-0006 | B6: ACC-NASA-STEM-ENGAGEMENT | C6: STEM Opportunities formerly Education | D6: Printed in S.Rept. 115-275 p.157 (FY2019: 2018 appropriation 100,000 / budget estimate blank / committee recommendation 110,000). | E6: 2026-09-25 | F6: 1 | G6: TRUE
A7: HN-0007 | B7: ACC-NASA-SPACETECH | C7: Exploration Research and Technology | D7: FY2019 Budget Appendix: the FY2019 budget request 'renames the Space Operations, Exploration, and Space Technology accounts as LEO and Spaceflight Operations, Deep Space Exploration Systems, and Exploration Research and Technology' -- account code 080-0131 matches Space Technology's own code. Printed for this account in H.Rept. 115-704 p.128 and S.Rept. 115-275 p.157 (FY2019). | E7: 2026-09-25 | F7: 1 | G7: TRUE
A8: HN-0008 | B8: ACC-NASA-SPACETECH | C8: Exploration Technology | D8: Same FY2019 rename proposal, FY2020 printed form. H.Rept. 116-101 p.148, S.Rept. 116-127 p.191 (FY2020). | E8: 2026-09-25 | F8: 1 | G8: TRUE
A9: HN-LHHS-0001 | B9: ACC-HHS-NIH-NIAAA | C9: National Institute on Alcohol Effects and Alcohol-Related Disorders | D9: FY2023 House: H.R. 8295 (reported) Title II heading and H.Rept. 117-403 Title II table p.815 (PDF), 'National Institute on Alcohol Effects and Alcohol-Related Disorders (NIAAA)'; also the FY2023 Senate draft explanatory statement's table. A proposed rename, not enacted: P.L. 117-328 and later laws keep 'National Institute on Alcohol Abuse and Alcoholism'. | F9: 0.95 | G9: FALSE
A10: HN-LHHS-0002 | B10: ACC-HHS-NIH-NIDA | C10: National Institute on Drugs and Addiction | D10: FY2023 House: H.R. 8295 (reported) Title II heading and H.Rept. 117-403 p.815 (PDF), 'National Institute on Drugs and Addiction (NIDA)'. A proposed rename, not enacted: P.L. 117-328 and later laws keep 'National Institute on Drug Abuse'. | F10: 0.95 | G10: FALSE
A11: HN-LHHS-0003 | B11: ACC-HHS-SAMHSA-TREATMENT | C11: Substance Use Services | D11: FY2023 House: H.Rept. 117-403 p.818 (PDF) section 'Substance Use Services' and 'Subtotal, Substance Use Services, appropriation'; the FY2023 Senate draft prints the same. P.L. 117-328 and later laws keep the heading 'Substance Abuse Treatment'. | F11: 0.95 | G11: FALSE
A12: HN-LHHS-0004 | B12: ACC-HHS-SAMHSA-PREVENTION | C12: Substance Use Prevention Services | D12: FY2023 House: H.Rept. 117-403 p.819 (PDF) 'Total, Substance Use Prevention Services, appropriation'; the FY2023 Senate draft prints the same. P.L. 117-328 and later laws keep the heading 'Substance Abuse Prevention'. | F12: 0.95 | G12: FALSE

Sheet Confirmed Absence
A1: confirmed_absence_id | B1: canonical_account_id | C1: fiscal_year | D1: stage | E1: amount_type | F1: component | G1: source_document_id | H1: evidence | I1: confirmed_date
A2: CA-0001 | B2: ACC-NASA-CONSTRUCTION | C2: 2017 | D2: President's Budget | E2: supplemental | G2: SRC-CRPT-114HRPT605 | H2: No Construction and environmental compliance and restoration (emergency) line anywhere in the comparative table (pp.106-118: Title III, Title V General Provisions and any Other Appropriations sections) for FY2017 President's Budget; read by OCR of every table page; Title III pp.114-115 read from the page images | I2: 2026-09-25
A3: CA-0002 | B3: ACC-NASA-CONSTRUCTION | C3: 2017 | D3: House Reported | E3: supplemental | G3: SRC-CRPT-114HRPT605 | H3: No Construction and environmental compliance and restoration (emergency) line anywhere in the comparative table (pp.106-118: Title III, Title V General Provisions and any Other Appropriations sections) for FY2017 House Reported; read by OCR of every table page; Title III pp.114-115 read from the page images | I3: 2026-09-25
A4: CA-0003 | B4: ACC-NASA-CONSTRUCTION | C4: 2017 | D4: Senate Reported | E4: supplemental | G4: SRC-CRPT-114SRPT239 | H4: No Construction and environmental compliance and restoration (emergency) line anywhere in the comparative table (pp.134-141: Title III, Title V General Provisions and any Other Appropriations sections) for FY2017 Senate Reported; read by text layer | I4: 2026-09-25
A5: CA-0004 | B5: ACC-NASA-CONSTRUCTION | C5: 2018 | D5: President's Budget | E5: supplemental | G5: SRC-CRPT-115HRPT231 | H5: No Construction and environmental compliance and restoration (emergency) line anywhere in the comparative table (pp.111-124: Title III, Title V General Provisions and any Other Appropriations sections) for FY2018 President's Budget; read by OCR of every table page; Title III pp.120-121 read from the page images | I5: 2026-09-25
A6: CA-0005 | B6: ACC-NASA-CONSTRUCTION | C6: 2018 | D6: House Reported | E6: supplemental | G6: SRC-CRPT-115HRPT231 | H6: No Construction and environmental compliance and restoration (emergency) line anywhere in the comparative table (pp.111-124: Title III, Title V General Provisions and any Other Appropriations sections) for FY2018 House Reported; read by OCR of every table page; Title III pp.120-121 read from the page images | I6: 2026-09-25
A7: CA-0006 | B7: ACC-NASA-CONSTRUCTION | C7: 2018 | D7: Senate Reported | E7: supplemental | G7: SRC-CRPT-115SRPT139 | H7: No Construction and environmental compliance and restoration (emergency) line anywhere in the comparative table (pp.135-143: Title III, Title V General Provisions and any Other Appropriations sections) for FY2018 Senate Reported; read by text layer | I7: 2026-09-25
A8: CA-0007 | B8: ACC-NASA-CONSTRUCTION | C8: 2019 | D8: President's Budget | E8: supplemental | G8: SRC-CRPT-115HRPT704 | H8: No Construction and environmental compliance and restoration (emergency) line anywhere in the comparative table (pp.120-135: Title III, Title V General Provisions and any Other Appropriations sections) for FY2019 President's Budget; read by OCR of every table page; Title III pp.128-129 read from the page images | I8: 2026-09-25
A9: CA-0008 | B9: ACC-NASA-CONSTRUCTION | C9: 2019 | D9: House Reported | E9: supplemental | G9: SRC-CRPT-115HRPT704 | H9: No Construction and environmental compliance and restoration (emergency) line anywhere in the comparative table (pp.120-135: Title III, Title V General Provisions and any Other Appropriations sections) for FY2019 House Reported; read by OCR of every table page; Title III pp.128-129 read from the page images | I9: 2026-09-25
A10: CA-0009 | B10: ACC-NASA-CONSTRUCTION | C10: 2019 | D10: Senate Reported | E10: supplemental | G10: SRC-CRPT-115SRPT275 | H10: the only Construction and Environmental Compliance and Restoration (emergency) line (p.161, P.L. 115-123 section) prints a figure in the 2018 appropriation column only; its Committee recommendation cell is blank (text layer); no other Construction and environmental compliance and restoration (emergency) line in the table (pp.152-161) | I10: 2026-09-25
A11: CA-0010 | B11: ACC-NASA-CONSTRUCTION | C11: 2019 | D11: Enacted | E11: supplemental | G11: SRC-CRPT-116HRPT101 | H11: No Construction and environmental compliance and restoration (emergency) line anywhere in the comparative table (pp.139-152: Title III, Title V General Provisions and any Other Appropriations sections) for FY2019 Enacted; read by OCR of every table page; Title III pp.148-149 read from the page images | I11: 2026-09-25
A12: CA-0011 | B12: ACC-NASA-CONSTRUCTION | C12: 2020 | D12: President's Budget | E12: supplemental | G12: SRC-CRPT-116HRPT101 | H12: No Construction and environmental compliance and restoration (emergency) line anywhere in the comparative table (pp.139-152: Title III, Title V General Provisions and any Other Appropriations sections) for FY2020 President's Budget; read by OCR of every table page; Title III pp.148-149 read from the page images | I12: 2026-09-25
A13: CA-0012 | B13: ACC-NASA-CONSTRUCTION | C13: 2020 | D13: House Reported | E13: supplemental | G13: SRC-CRPT-116HRPT101 | H13: No Construction and environmental compliance and restoration (emergency) line anywhere in the comparative table (pp.139-152: Title III, Title V General Provisions and any Other Appropriations sections) for FY2020 House Reported; read by OCR of every table page; Title III pp.148-149 read from the page images | I13: 2026-09-25
... A222: CA-LHHS-0024 | B222: ACC-HHS-GP-ADOPTION-INCENTIVES-RESCISSION | C222: 2025 | D222: Enacted | E222: rescission | G222: SRC-PLAW-119PUBL4 | H222: P.L. 119-4 (Full-Year Continuing Appropriations Act, 2025, division A) provides no Adoption Incentives rescission for FY2025. Deciding text, sec. 1101(a)(8) (139 Stat. 11; PDF p. 3; text layer): it continues 'The Departments of Labor, Health and Human Services, and Education, and Related Agencies Appropriations Act, 2024 (division D of Public Law 118-47), except section 240 shall be applied by substituting "$1,471,000,000" for "$1,250,000,000" ..., except sections 241 and 310, ...'. Section 241 of that division (P.L. 118-47, 138 Stat. 681) is the FY2024 rescission of $70,000,000 of P.L. 117-328 Children and Families Services Programs funds 'for grants to States for incentive payments, as defined by section 473A of the Social Security Act' -- the line the FY2024 tables print as 'Adoption Incentives (rescission)' -70,000. Sec. 1105 continues the referenced Acts' provisions only 'Except as otherwise expressly provided in this division'. The Labor-HHS title of the CR (title IX, secs. 1901-1912, 139 Stat. 31-33) adds no such rescission, and the whole law's text layer has no 'adoption', '473A' or 'incentive payments'. No committee table covers FY2025 Enacted (H.Rept. 119-271's 'FY 2025 Estimate' column is operating plans, held back). | I222: 2026-10-06
A223: CA-LHHS-0025 | B223: ACC-HHS-GP-NEF-RESCISSION | C223: 2025 | D223: Enacted | E223: rescission | F223: emergency | G223: SRC-CRPT-119HRPT271 | H223: No 'Nonrecurring expenses fund, HHS (rescission) (emergency)' line in H.Rept. 119-271's FY 2025 Estimate column. Searched: the whole Title II comparative table, PDF pp. 334-366 (printed pp. 330-362); the table pages have no text layer and were read from the page images (every row transcribed by vision). Title II General Provisions, PDF p. 365 (printed p. 361), FY 2025 Estimate column: Medicare Operations (Sec. 226) 455,000 and Nonrecurring expenses fund, HHS (rescission) (Sec. 234) -1,471,000, with 'Total, Title II General Provisions' -1,016,000 equal to those two lines. P.L. 119-4 sec. 1101(a)(8) continues Div. D sec. 240 except for 'amounts that were previously designated by the Congress as being for an emergency requirement'. The column is the report's 'FY 2025 Operating Plans and other available information' (pp.319-320); FY2025 was a full-year CR (P.L. 119-4). | I223: 2026-10-07
A224: CA-LHHS-0028 | B224: ACC-HHS-CMS-MEDICAID | C224: 2023 | D224: President's Budget | E224: budget authority | G224: SRC-CRPT-117HRPT403 | H224: No row for this account's headline figure ('Total, Grants to States for Medicaid') in H.Rept.117-403 Title II table pp. 802-838 (PDF; printed pp. 798-834, read by vision) for FY2023 President's Budget. The document prints only 'Total, Grants to States for Medicaid, appropriated in this bill' 564,937,564 (p.821); 'Total, Medicaid Program Level, available this fiscal year' 533,079,108 (p.821) -- not recorded: each is another scope of the headline (component kind 'view'), which needs the headline it is a view of. | I224: 2026-10-06
A225: CA-LHHS-0029 | B225: ACC-HHS-CMS-MEDICAID | C225: 2023 | D225: House Reported | E225: budget authority | G225: SRC-CRPT-117HRPT403 | H225: No row for this account's headline figure ('Total, Grants to States for Medicaid') in H.Rept.117-403 Title II table pp. 802-838 (PDF; printed pp. 798-834, read by vision) for FY2023 House Reported. The document prints only 'Total, Grants to States for Medicaid, appropriated in this bill' 564,937,564 (p.821); 'Total, Medicaid Program Level, available this fiscal year' 533,079,108 (p.821) -- not recorded: each is another scope of the headline (component kind 'view'), which needs the headline it is a view of. | I225: 2026-10-06
A226: CA-LHHS-0030 | B226: ACC-HHS-ASPR-TOTAL | C226: 2023 | D226: President's Budget | E226: budget authority | G226: SRC-CRPT-117HRPT403 | H226: No row for this account's headline figure ('Total, Administration for Strategic Preparedness and Response') in H.Rept.117-403 Title II table pp. 802-838 (PDF; printed pp. 798-834, read by vision) for FY2023 President's Budget. The report has no ASPR operating division: the preparedness programs (BARDA, Strategic National Stockpile, Project BioShield, Pandemic Influenza) print under the Office of the Secretary's Public Health and Social Services Emergency Fund, whose total also holds non-ASPR lines (Cybersecurity, Office of National Security, OASH): 'Total, PHSSEF' 3,814,610 (p.836) -- a different scope, not recorded. | I226: 2026-10-06
A227: CA-LHHS-0031 | B227: ACC-HHS-ASPR-TOTAL | C227: 2023 | D227: House Reported | E227: budget authority | G227: SRC-CRPT-117HRPT403 | H227: No row for this account's headline figure ('Total, Administration for Strategic Preparedness and Response') in H.Rept.117-403 Title II table pp. 802-838 (PDF; printed pp. 798-834, read by vision) for FY2023 House Reported. The report has no ASPR operating division: the preparedness programs (BARDA, Strategic National Stockpile, Project BioShield, Pandemic Influenza) print under the Office of the Secretary's Public Health and Social Services Emergency Fund, whose total also holds non-ASPR lines (Cybersecurity, Office of National Security, OASH): 'Total, PHSSEF' 3,699,356 (p.836) -- a different scope, not recorded. | I227: 2026-10-06
A228: CA-LHHS-0032 | B228: ACC-HHS-CMS-MEDICAID | C228: 2023 | D228: Senate Reported | E228: budget authority | G228: SRC-EXPL-LHHS-FY2023-SENATE | H228: No row for this account's headline figure ('Total, Grants to States for Medicaid') in the Senate draft explanatory statement's Title II table pp. 399-419 (text layer) for FY2023 Senate Reported. The document prints only 'Total, Medicaid Program Level, available this fiscal year' 533,079,108 (p.409); 'Total, Grants to States for Medicaid, appropriated in this bill' 564,937,564 (p.409) -- not recorded: each is another scope of the headline (component kind 'view'), which needs the headline it is a view of. | I228: 2026-10-06
A229: CA-LHHS-0033 | B229: ACC-HHS-ASPR-TOTAL | C229: 2023 | D229: Senate Reported | E229: budget authority | G229: SRC-EXPL-LHHS-FY2023-SENATE | H229: No row for this account's headline figure ('Total, Administration for Strategic Preparedness and Response') in the Senate draft explanatory statement's Title II table pp. 399-419 (text layer) for FY2023 Senate Reported. The document prints only no ASPR operating division: the preparedness programs (BARDA, Strategic National Stockpile, Project BioShield, Pandemic Influenza) print under the Office of the Secretary's Public Health and Social Services Emergency Fund ('Total, PHSSEF' 3,639,479, p.419), whose total also holds non-ASPR lines -- a different scope, not recorded. | I229: 2026-10-06
A230: CA-LHHS-0034 | B230: ACC-HHS-GP-MEDICARE-OPERATIONS | C230: 2023 | D230: Senate Reported | E230: budget authority | G230: SRC-EXPL-LHHS-FY2023-SENATE | H230: No 'Medicare Operations (Sec. nnn)' line anywhere in the Senate draft explanatory statement for FY2023 (whole text layer, 437 pages, searched for /Medicare Operations|Traditional Medicare Program/; the Title II table pp. 399-419 and the table's end p.437 included). | I230: 2026-10-06
A231: CA-LHHS-0035 | B231: ACC-HHS-GP-ADOPTION-INCENTIVES-RESCISSION | C231: 2023 | D231: Senate Reported | E231: rescission | G231: SRC-EXPL-LHHS-FY2023-SENATE | H231: No 'Adoption Incentives (rescission)' line anywhere in the Senate draft explanatory statement for FY2023 (whole text layer, 437 pages, searched for /Adoption Incentives \(rescission/; the Title II table pp. 399-419 and the table's end p.437 included). | I231: 2026-10-06
A232: CA-LHHS-0036 | B232: ACC-HHS-GP-MEDICARE-LIMITATION | C232: 2023 | D232: Senate Reported | E232: budget authority | G232: SRC-EXPL-LHHS-FY2023-SENATE | H232: No 'Limitation for Title XVIII of the Social Security Act' line anywhere in the Senate draft explanatory statement for FY2023 (whole text layer, 437 pages, searched for /Title XVIII/; the Title II table pp. 399-419 and the table's end p.437 included). | I232: 2026-10-06
A233: CA-LHHS-0037 | B233: ACC-HHS-CDC-PROGRAM-SUPPORT | C233: 2023 | D233: President's Budget | E233: budget authority | G233: SRC-CRPT-117HRPT403 | H233: No budget-authority row for 'CDC-Wide Activities and Program Support' in the Title II table (PDF p.813) for FY2023 President's Budget: the section prints its lines and a parenthesized 'Subtotal' that includes the Prevention and Public Health Fund transfer (program level) -- not recorded. | I233: 2026-10-06
A234: CA-LHHS-0038 | B234: ACC-HHS-CDC-PROGRAM-SUPPORT | C234: 2023 | D234: House Reported | E234: budget authority | G234: SRC-CRPT-117HRPT403 | H234: No budget-authority row for 'CDC-Wide Activities and Program Support' in the Title II table (PDF p.813) for FY2023 House Reported: the section prints its lines and a parenthesized 'Subtotal' that includes the Prevention and Public Health Fund transfer (program level) -- not recorded. | I234: 2026-10-06
A235: CA-LHHS-0039 | B235: ACC-HHS-CDC-PROGRAM-SUPPORT | C235: 2023 | D235: Senate Reported | E235: budget authority | G235: SRC-EXPL-LHHS-FY2023-SENATE | H235: No budget-authority row for 'CDC-Wide Activities and Program Support' in the Title II table (PDF p.405) for FY2023 Senate Reported: the section prints its lines and a parenthesized 'Subtotal' that includes the Prevention and Public Health Fund transfer (program level) -- not recorded. | I235: 2026-10-06

Sheet Appropriations Observation
A1: observation_id | B1: canonical_account_id | C1: fiscal_year | D1: stage | E1: chamber | F1: bill_id | G1: report_id | H1: amount | I1: amount_type | J1: component | K1: offsetting_collections | L1: transfer_link_account_id | M1: source_document_id | N1: source_page | O1: source_table_or_section | P1: extraction_method | Q1: confidence | R1: verification_status | S1: bill_url | T1: report_jes_url | U1: headline_observation_id
A2: OBS-0001 | B2: ACC-OSTP | C2: 2026 | D2: Enacted | E2: N/A | F2: =IFERROR(""&INDEX('Bill Report Reference'!$E$2:$E$59,MATCH(INDEX(Account!$J$2:$J$131,MATCH($B2,Account!$A$2:$A$131,0))&"-"&$C2&"-"&$D2,'Bill Report Reference'!$I$2:$I$59,0)),"") -> P.L.119-74 | G2: =IFERROR(""&INDEX('Bill Report Reference'!$F$2:$F$59,MATCH(INDEX(Account!$J$2:$J$131,MATCH($B2,Account!$A$2:$A$131,0))&"-"&$C2&"-"&$D2,'Bill Report Reference'!$I$2:$I$59,0)),"") -> JES_CJS_P.L.119-74 | H2: 7965000 | I2: budget authority | K2: FALSE | M2: SRC-EXPL-FY2026-PB | N2: 128-130 | O2: Title III, Executive Office of the President, Office of Science and Technology Policy | P2: human-entered | Q2: 1 | R2: human-verified | S2: =IFERROR(""&INDEX('Bill Report Reference'!$G$2:$G$59,MATCH(INDEX(Account!$J$2:$J$131,MATCH($B2,Account!$A$2:$A$131,0))&"-"&$C2&"-"&$D2,'Bill Report Reference'!$I$2:$I$59,0)),"") -> https://www.govinfo.gov/content/pkg/PLAW-119publ74/pdf/PLAW-119publ74.pdf | T2: =IFERROR(""&INDEX('Bill Report Reference'!$H$2:$H$59,MATCH(INDEX(Account!$J$2:$J$131,MATCH($B2,Account!$A$2:$A$131,0))&"-"&$C2&"-"&$D2,'Bill Report Reference'!$I$2:$I$59,0)),"") -> https://rules.house.gov/sites/evo-subsites/rules.house.gov/files/documents/division-a-commerce-justice-science_0.pdf
A3: OBS-0002 | B3: ACC-OSTP | C3: 2026 | D3: Senate Reported | E3: Senate | F3: =IFERROR(""&INDEX('Bill Report Reference'!$E$2:$E$59,MATCH(INDEX(Account!$J$2:$J$131,MATCH($B3,Account!$A$2:$A$131,0))&"-"&$C3&"-"&$D3,'Bill Report Reference'!$I$2:$I$59,0)),"") -> S.2354 | G3: =IFERROR(""&INDEX('Bill Report Reference'!$F$2:$F$59,MATCH(INDEX(Account!$J$2:$J$131,MATCH($B3,Account!$A$2:$A$131,0))&"-"&$C3&"-"&$D3,'Bill Report Reference'!$I$2:$I$59,0)),"") -> S.Rept.119-44 | H3: 7965000 | I3: budget authority | K3: FALSE | M3: SRC-CRPT-119SRPT44 | N3: 217-219 | O3: Title III, Executive Office of the President, Office of Science and Technology Policy | P3: human-entered | Q3: 1 | R3: human-verified | S3: =IFERROR(""&INDEX('Bill Report Reference'!$G$2:$G$59,MATCH(INDEX(Account!$J$2:$J$131,MATCH($B3,Account!$A$2:$A$131,0))&"-"&$C3&"-"&$D3,'Bill Report Reference'!$I$2:$I$59,0)),"") -> https://www.congress.gov/119/bills/s2354/BILLS-119s2354rs.pdf | T3: =IFERROR(""&INDEX('Bill Report Reference'!$H$2:$H$59,MATCH(INDEX(Account!$J$2:$J$131,MATCH($B3,Account!$A$2:$A$131,0))&"-"&$C3&"-"&$D3,'Bill Report Reference'!$I$2:$I$59,0)),"") -> https://www.congress.gov/119/crpt/srpt44/CRPT-119srpt44.pdf
A4: OBS-0003 | B4: ACC-OSTP | C4: 2026 | D4: House Reported | E4: House | F4: =IFERROR(""&INDEX('Bill Report Reference'!$E$2:$E$59,MATCH(INDEX(Account!$J$2:$J$131,MATCH($B4,Account!$A$2:$A$131,0))&"-"&$C4&"-"&$D4,'Bill Report Reference'!$I$2:$I$59,0)),"") -> H.R.5342 | G4: =IFERROR(""&INDEX('Bill Report Reference'!$F$2:$F$59,MATCH(INDEX(Account!$J$2:$J$131,MATCH($B4,Account!$A$2:$A$131,0))&"-"&$C4&"-"&$D4,'Bill Report Reference'!$I$2:$I$59,0)),"") -> H.Rept.119-272 | H4: 7965000 | I4: budget authority | K4: FALSE | M4: SRC-CRPT-119HRPT272 | N4: 256-257 | O4: Title III, Executive Office of the President, Office of Science and Technology Policy | P4: human-entered | Q4: 1 | R4: human-verified | S4: =IFERROR(""&INDEX('Bill Report Reference'!$G$2:$G$59,MATCH(INDEX(Account!$J$2:$J$131,MATCH($B4,Account!$A$2:$A$131,0))&"-"&$C4&"-"&$D4,'Bill Report Reference'!$I$2:$I$59,0)),"") -> https://www.govinfo.gov/content/pkg/BILLS-119hr5342rh/pdf/BILLS-119hr5342rh.pdf | T4: =IFERROR(""&INDEX('Bill Report Reference'!$H$2:$H$59,MATCH(INDEX(Account!$J$2:$J$131,MATCH($B4,Account!$A$2:$A$131,0))&"-"&$C4&"-"&$D4,'Bill Report Reference'!$I$2:$I$59,0)),"") -> https://www.congress.gov/119/crpt/hrpt272/CRPT-119hrpt272.pdf
A5: OBS-0004 | B5: ACC-OSTP | C5: 2026 | D5: President's Budget | E5: N/A | F5: =IFERROR(""&INDEX('Bill Report Reference'!$E$2:$E$59,MATCH(INDEX(Account!$J$2:$J$131,MATCH($B5,Account!$A$2:$A$131,0))&"-"&$C5&"-"&$D5,'Bill Report Reference'!$I$2:$I$59,0)),"") -> PREX 2.8:2026/APP | G5: =IFERROR(""&INDEX('Bill Report Reference'!$F$2:$F$59,MATCH(INDEX(Account!$J$2:$J$131,MATCH($B5,Account!$A$2:$A$131,0))&"-"&$C5&"-"&$D5,'Bill Report Reference'!$I$2:$I$59,0)),"") -> N/A | H5: 7965000 | I5: budget authority | K5: FALSE | M5: SRC-EXPL-FY2026-PB | N5: 128-130 | O5: Title III, Executive Office of the President, Office of Science and Technology Policy | P5: human-entered | Q5: 1 | R5: human-verified | S5: =IFERROR(""&INDEX('Bill Report Reference'!$G$2:$G$59,MATCH(INDEX(Account!$J$2:$J$131,MATCH($B5,Account!$A$2:$A$131,0))&"-"&$C5&"-"&$D5,'Bill Report Reference'!$I$2:$I$59,0)),"") -> https://www.govinfo.gov/content/pkg/BUDGET-2026-APP/pdf/BUDGET-2026-APP.pdf | T5: =IFERROR(""&INDEX('Bill Report Reference'!$H$2:$H$59,MATCH(INDEX(Account!$J$2:$J$131,MATCH($B5,Account!$A$2:$A$131,0))&"-"&$C5&"-"&$D5,'Bill Report Reference'!$I$2:$I$59,0)),"") -> N/A
A6: OBS-0005 | B6: ACC-OSTP | C6: 2025 | D6: Enacted | E6: N/A | F6: =IFERROR(""&INDEX('Bill Report Reference'!$E$2:$E$59,MATCH(INDEX(Account!$J$2:$J$131,MATCH($B6,Account!$A$2:$A$131,0))&"-"&$C6&"-"&$D6,'Bill Report Reference'!$I$2:$I$59,0)),"") -> P.L.119-4 | G6: =IFERROR(""&INDEX('Bill Report Reference'!$F$2:$F$59,MATCH(INDEX(Account!$J$2:$J$131,MATCH($B6,Account!$A$2:$A$131,0))&"-"&$C6&"-"&$D6,'Bill Report Reference'!$I$2:$I$59,0)),"") -> N/A | H6: 7965000 | I6: budget authority | K6: FALSE | M6: SRC-CRPT-119HRPT272 | N6: 256-257 | O6: Title III, Executive Office of the President, Office of Science and Technology Policy | P6: human-entered | Q6: 1 | R6: human-verified | S6: =IFERROR(""&INDEX('Bill Report Reference'!$G$2:$G$59,MATCH(INDEX(Account!$J$2:$J$131,MATCH($B6,Account!$A$2:$A$131,0))&"-"&$C6&"-"&$D6,'Bill Report Reference'!$I$2:$I$59,0)),"") -> https://www.govinfo.gov/content/pkg/PLAW-119publ4/pdf/PLAW-119publ4.pdf | T6: =IFERROR(""&INDEX('Bill Report Reference'!$H$2:$H$59,MATCH(INDEX(Account!$J$2:$J$131,MATCH($B6,Account!$A$2:$A$131,0))&"-"&$C6&"-"&$D6,'Bill Report Reference'!$I$2:$I$59,0)),"") -> N/A
A7: OBS-0006 | B7: ACC-OSTP | C7: 2025 | D7: Senate Reported | E7: Senate | F7: =IFERROR(""&INDEX('Bill Report Reference'!$E$2:$E$59,MATCH(INDEX(Account!$J$2:$J$131,MATCH($B7,Account!$A$2:$A$131,0))&"-"&$C7&"-"&$D7,'Bill Report Reference'!$I$2:$I$59,0)),"") -> S.4795 | G7: =IFERROR(""&INDEX('Bill Report Reference'!$F$2:$F$59,MATCH(INDEX(Account!$J$2:$J$131,MATCH($B7,Account!$A$2:$A$131,0))&"-"&$C7&"-"&$D7,'Bill Report Reference'!$I$2:$I$59,0)),"") -> S.Rept.118-198 | H7: 7965000 | I7: budget authority | K7: FALSE | M7: SRC-CRPT-118SRPT198 | N7: 227-228 | O7: Title III, Executive Office of the President, Office of Science and Technology Policy | P7: human-entered | Q7: 1 | R7: human-verified | S7: =IFERROR(""&INDEX('Bill Report Reference'!$G$2:$G$59,MATCH(INDEX(Account!$J$2:$J$131,MATCH($B7,Account!$A$2:$A$131,0))&"-"&$C7&"-"&$D7,'Bill Report Reference'!$I$2:$I$59,0)),"") -> https://www.congress.gov/118/bills/s4795/BILLS-118s4795rs.pdf | T7: =IFERROR(""&INDEX('Bill Report Reference'!$H$2:$H$59,MATCH(INDEX(Account!$J$2:$J$131,MATCH($B7,Account!$A$2:$A$131,0))&"-"&$C7&"-"&$D7,'Bill Report Reference'!$I$2:$I$59,0)),"") -> https://www.congress.gov/118/crpt/srpt198/CRPT-118srpt198.pdf
A8: OBS-0007 | B8: ACC-OSTP | C8: 2025 | D8: House Reported | E8: House | F8: =IFERROR(""&INDEX('Bill Report Reference'!$E$2:$E$59,MATCH(INDEX(Account!$J$2:$J$131,MATCH($B8,Account!$A$2:$A$131,0))&"-"&$C8&"-"&$D8,'Bill Report Reference'!$I$2:$I$59,0)),"") -> H.R.9026 | G8: =IFERROR(""&INDEX('Bill Report Reference'!$F$2:$F$59,MATCH(INDEX(Account!$J$2:$J$131,MATCH($B8,Account!$A$2:$A$131,0))&"-"&$C8&"-"&$D8,'Bill Report Reference'!$I$2:$I$59,0)),"") -> H.Rept.118-582 | H8: 5544000 | I8: budget authority | K8: FALSE | M8: SRC-CRPT-118HRPT582 | N8: 247-248 | O8: Title III, Executive Office of the President, Office of Science and Technology Policy | P8: human-entered | Q8: 1 | R8: human-verified | S8: =IFERROR(""&INDEX('Bill Report Reference'!$G$2:$G$59,MATCH(INDEX(Account!$J$2:$J$131,MATCH($B8,Account!$A$2:$A$131,0))&"-"&$C8&"-"&$D8,'Bill Report Reference'!$I$2:$I$59,0)),"") -> https://www.govinfo.gov/content/pkg/BILLS-118hr9026rh/pdf/BILLS-118hr9026rh.pdf | T8: =IFERROR(""&INDEX('Bill Report Reference'!$H$2:$H$59,MATCH(INDEX(Account!$J$2:$J$131,MATCH($B8,Account!$A$2:$A$131,0))&"-"&$C8&"-"&$D8,'Bill Report Reference'!$I$2:$I$59,0)),"") -> https://www.congress.gov/118/crpt/hrpt582/CRPT-118hrpt582.pdf
A9: OBS-0008 | B9: ACC-OSTP | C9: 2025 | D9: President's Budget | E9: N/A | F9: =IFERROR(""&INDEX('Bill Report Reference'!$E$2:$E$59,MATCH(INDEX(Account!$J$2:$J$131,MATCH($B9,Account!$A$2:$A$131,0))&"-"&$C9&"-"&$D9,'Bill Report Reference'!$I$2:$I$59,0)),"") -> PREX 2.8:2025/APP | G9: =IFERROR(""&INDEX('Bill Report Reference'!$F$2:$F$59,MATCH(INDEX(Account!$J$2:$J$131,MATCH($B9,Account!$A$2:$A$131,0))&"-"&$C9&"-"&$D9,'Bill Report Reference'!$I$2:$I$59,0)),"") -> N/A | H9: 7965000 | I9: budget authority | K9: FALSE | M9: SRC-CRPT-118HRPT582 | N9: 247-248 | O9: Title III, Executive Office of the President, Office of Science and Technology Policy | P9: human-entered | Q9: 1 | R9: human-verified | S9: =IFERROR(""&INDEX('Bill Report Reference'!$G$2:$G$59,MATCH(INDEX(Account!$J$2:$J$131,MATCH($B9,Account!$A$2:$A$131,0))&"-"&$C9&"-"&$D9,'Bill Report Reference'!$I$2:$I$59,0)),"") -> https://www.govinfo.gov/content/pkg/BUDGET-2025-APP/pdf/BUDGET-2025-APP.pdf | T9: =IFERROR(""&INDEX('Bill Report Reference'!$H$2:$H$59,MATCH(INDEX(Account!$J$2:$J$131,MATCH($B9,Account!$A$2:$A$131,0))&"-"&$C9&"-"&$D9,'Bill Report Reference'!$I$2:$I$59,0)),"") -> N/A
A10: OBS-0009 | B10: ACC-OSTP | C10: 2024 | D10: Enacted | E10: N/A | F10: =IFERROR(""&INDEX('Bill Report Reference'!$E$2:$E$59,MATCH(INDEX(Account!$J$2:$J$131,MATCH($B10,Account!$A$2:$A$131,0))&"-"&$C10&"-"&$D10,'Bill Report Reference'!$I$2:$I$59,0)),"") -> P.L.118-42 | G10: =IFERROR(""&INDEX('Bill Report Reference'!$F$2:$F$59,MATCH(INDEX(Account!$J$2:$J$131,MATCH($B10,Account!$A$2:$A$131,0))&"-"&$C10&"-"&$D10,'Bill Report Reference'!$I$2:$I$59,0)),"") -> JES_CJS_P.L.118-42 | H10: 7965000 | I10: budget authority | K10: FALSE | M10: SRC-CRPT-118HRPT582 | N10: 247-248 | O10: Title III, Executive Office of the President, Office of Science and Technology Policy | P10: human-entered | Q10: 1 | R10: human-verified | S10: =IFERROR(""&INDEX('Bill Report Reference'!$G$2:$G$59,MATCH(INDEX(Account!$J$2:$J$131,MATCH($B10,Account!$A$2:$A$131,0))&"-"&$C10&"-"&$D10,'Bill Report Reference'!$I$2:$I$59,0)),"") -> https://www.govinfo.gov/content/pkg/PLAW-118publ42/pdf/PLAW-118publ42.pdf | T10: =IFERROR(""&INDEX('Bill Report Reference'!$H$2:$H$59,MATCH(INDEX(Account!$J$2:$J$131,MATCH($B10,Account!$A$2:$A$131,0))&"-"&$C10&"-"&$D10,'Bill Report Reference'!$I$2:$I$59,0)),"") -> https://docs.house.gov/billsthisweek/20240304/FY24%20CJS%20Conference%20JES%20scan%203.3.24.pdf
A11: OBS-0010 | B11: ACC-OSTP | C11: 2024 | D11: Senate Reported | E11: Senate | F11: =IFERROR(""&INDEX('Bill Report Reference'!$E$2:$E$59,MATCH(INDEX(Account!$J$2:$J$131,MATCH($B11,Account!$A$2:$A$131,0))&"-"&$C11&"-"&$D11,'Bill Report Reference'!$I$2:$I$59,0)),"") -> S.2321 | G11: =IFERROR(""&INDEX('Bill Report Reference'!$F$2:$F$59,MATCH(INDEX(Account!$J$2:$J$131,MATCH($B11,Account!$A$2:$A$131,0))&"-"&$C11&"-"&$D11,'Bill Report Reference'!$I$2:$I$59,0)),"") -> S.Rept.118-62 | H11: 7965000 | I11: budget authority | K11: FALSE | M11: SRC-CRPT-118SRPT62 | N11: 219-220 | O11: Title III, Executive Office of the President, Office of Science and Technology Policy | P11: human-entered | Q11: 1 | R11: human-verified | S11: =IFERROR(""&INDEX('Bill Report Reference'!$G$2:$G$59,MATCH(INDEX(Account!$J$2:$J$131,MATCH($B11,Account!$A$2:$A$131,0))&"-"&$C11&"-"&$D11,'Bill Report Reference'!$I$2:$I$59,0)),"") -> https://www.congress.gov/118/bills/s2321/BILLS-118s2321rs.pdf | T11: =IFERROR(""&INDEX('Bill Report Reference'!$H$2:$H$59,MATCH(INDEX(Account!$J$2:$J$131,MATCH($B11,Account!$A$2:$A$131,0))&"-"&$C11&"-"&$D11,'Bill Report Reference'!$I$2:$I$59,0)),"") -> https://www.congress.gov/118/crpt/srpt62/CRPT-118srpt62.pdf
A12: OBS-0011 | B12: ACC-OSTP | C12: 2024 | D12: House Reported | E12: House | F12: =IFERROR(""&INDEX('Bill Report Reference'!$E$2:$E$59,MATCH(INDEX(Account!$J$2:$J$131,MATCH($B12,Account!$A$2:$A$131,0))&"-"&$C12&"-"&$D12,'Bill Report Reference'!$I$2:$I$59,0)),"") -> H.R.5893 | G12: =IFERROR(""&INDEX('Bill Report Reference'!$F$2:$F$59,MATCH(INDEX(Account!$J$2:$J$131,MATCH($B12,Account!$A$2:$A$131,0))&"-"&$C12&"-"&$D12,'Bill Report Reference'!$I$2:$I$59,0)),"") -> JES_CJS_H.R.5893 | H12: 5544000 | I12: budget authority | K12: FALSE | M12: SRC-EXPL-FY2024-HOUSE | N12: 170-171 | O12: Title III, Executive Office of the President, Office of Science and Technology Policy | P12: human-entered | Q12: 1 | R12: human-verified | S12: =IFERROR(""&INDEX('Bill Report Reference'!$G$2:$G$59,MATCH(INDEX(Account!$J$2:$J$131,MATCH($B12,Account!$A$2:$A$131,0))&"-"&$C12&"-"&$D12,'Bill Report Reference'!$I$2:$I$59,0)),"") -> https://www.congress.gov/118/bills/hr5893/BILLS-118hr5893ih.pdf | T12: =IFERROR(""&INDEX('Bill Report Reference'!$H$2:$H$59,MATCH(INDEX(Account!$J$2:$J$131,MATCH($B12,Account!$A$2:$A$131,0))&"-"&$C12&"-"&$D12,'Bill Report Reference'!$I$2:$I$59,0)),"") -> https://appropriations.house.gov/sites/evo-subsites/republicans-appropriations.house.gov/files/FY24-CJS-Explanatory-Materials.pdf
A13: OBS-0012 | B13: ACC-OSTP | C13: 2024 | D13: President's Budget | E13: N/A | F13: =IFERROR(""&INDEX('Bill Report Reference'!$E$2:$E$59,MATCH(INDEX(Account!$J$2:$J$131,MATCH($B13,Account!$A$2:$A$131,0))&"-"&$C13&"-"&$D13,'Bill Report Reference'!$I$2:$I$59,0)),"") -> PREX 2.8:2024/APP | G13: =IFERROR(""&INDEX('Bill Report Reference'!$F$2:$F$59,MATCH(INDEX(Account!$J$2:$J$131,MATCH($B13,Account!$A$2:$A$131,0))&"-"&$C13&"-"&$D13,'Bill Report Reference'!$I$2:$I$59,0)),"") -> N/A | H13: 8195000 | I13: budget authority | K13: FALSE | M13: SRC-CRPT-118SRPT62 | N13: 219-220 | O13: Title III, Executive Office of the President, Office of Science and Technology Policy | P13: human-entered | Q13: 1 | R13: human-verified | S13: =IFERROR(""&INDEX('Bill Report Reference'!$G$2:$G$59,MATCH(INDEX(Account!$J$2:$J$131,MATCH($B13,Account!$A$2:$A$131,0))&"-"&$C13&"-"&$D13,'Bill Report Reference'!$I$2:$I$59,0)),"") -> https://www.govinfo.gov/content/pkg/BUDGET-2024-APP/pdf/BUDGET-2024-APP.pdf | T13: =IFERROR(""&INDEX('Bill Report Reference'!$H$2:$H$59,MATCH(INDEX(Account!$J$2:$J$131,MATCH($B13,Account!$A$2:$A$131,0))&"-"&$C13&"-"&$D13,'Bill Report Reference'!$I$2:$I$59,0)),"") -> N/A
... A614: OBS-0658 | B614: ACC-NASA-CONSTRUCTION | C614: 2024 | D614: House Reported | E614: House | F614: =IFERROR(""&INDEX('Bill Report Reference'!$E$2:$E$59,MATCH(INDEX(Account!$J$2:$J$131,MATCH($B614,Account!$A$2:$A$131,0))&"-"&$C614&"-"&$D614,'Bill Report Reference'!$I$2:$I$59,0)),"") -> H.R.5893 | G614: =IFERROR(""&INDEX('Bill Report Reference'!$F$2:$F$59,MATCH(INDEX(Account!$J$2:$J$131,MATCH($B614,Account!$A$2:$A$131,0))&"-"&$C614&"-"&$D614,'Bill Report Reference'!$I$2:$I$59,0)),"") -> JES_CJS_H.R.5893 | H614: 0 | I614: supplemental | K614: FALSE | M614: SRC-EXPL-FY2024-HOUSE | N614: 170-171 | O614: Title III, NASA, Construction and Environmental Compliance and Restoration (emergency) | P614: human-entered | Q614: 1 | R614: human-verified | S614: =IFERROR(""&INDEX('Bill Report Reference'!$G$2:$G$59,MATCH(INDEX(Account!$J$2:$J$131,MATCH($B614,Account!$A$2:$A$131,0))&"-"&$C614&"-"&$D614,'Bill Report Reference'!$I$2:$I$59,0)),"") -> https://www.congress.gov/118/bills/hr5893/BILLS-118hr5893ih.pdf | T614: =IFERROR(""&INDEX('Bill Report Reference'!$H$2:$H$59,MATCH(INDEX(Account!$J$2:$J$131,MATCH($B614,Account!$A$2:$A$131,0))&"-"&$C614&"-"&$D614,'Bill Report Reference'!$I$2:$I$59,0)),"") -> https://appropriations.house.gov/sites/evo-subsites/republicans-appropriations.house.gov/files/FY24-CJS-Explanatory-Materials.pdf
A615: OBS-0660 | B615: ACC-NASA-CONSTRUCTION | C615: 2023 | D615: Enacted | E615: N/A | F615: =IFERROR(""&INDEX('Bill Report Reference'!$E$2:$E$59,MATCH(INDEX(Account!$J$2:$J$131,MATCH($B615,Account!$A$2:$A$131,0))&"-"&$C615&"-"&$D615,'Bill Report Reference'!$I$2:$I$59,0)),"") -> P.L.117-328 | G615: =IFERROR(""&INDEX('Bill Report Reference'!$F$2:$F$59,MATCH(INDEX(Account!$J$2:$J$131,MATCH($B615,Account!$A$2:$A$131,0))&"-"&$C615&"-"&$D615,'Bill Report Reference'!$I$2:$I$59,0)),"") -> JES_CJS_P.L.117-328 | H615: 556400000 | I615: supplemental | J615: supplemental_act | K615: FALSE | M615: SRC-CRPT-118SRPT62 | N615: 224 | O615: P.L. 117-328, Division N (Disaster Relief Supplemental Appropriations Act, 2023), Title III, 136 Stat. 5205-5206: two appropriations to "Construction and Environmental Compliance and Restoration", $189,400,000 + $367,000,000 = $556,400,000 (the report prints the sum). | P615: human-entered | Q615: 1 | R615: human-verified | S615: =IFERROR(""&INDEX('Bill Report Reference'!$G$2:$G$59,MATCH(INDEX(Account!$J$2:$J$131,MATCH($B615,Account!$A$2:$A$131,0))&"-"&$C615&"-"&$D615,'Bill Report Reference'!$I$2:$I$59,0)),"") -> https://www.govinfo.gov/content/pkg/PLAW-117publ328/pdf/PLAW-117publ328.pdf | T615: =IFERROR(""&INDEX('Bill Report Reference'!$H$2:$H$59,MATCH(INDEX(Account!$J$2:$J$131,MATCH($B615,Account!$A$2:$A$131,0))&"-"&$C615&"-"&$D615,'Bill Report Reference'!$I$2:$I$59,0)),"") -> https://www.govinfo.gov/content/pkg/CPRT-117HPRT50347/pdf/CPRT-117HPRT50347.pdf
A616: OBS-0661 | B616: ACC-NASA-CONSTRUCTION | C616: 2023 | D616: Senate Reported | E616: Senate | F616: =IFERROR(""&INDEX('Bill Report Reference'!$E$2:$E$59,MATCH(INDEX(Account!$J$2:$J$131,MATCH($B616,Account!$A$2:$A$131,0))&"-"&$C616&"-"&$D616,'Bill Report Reference'!$I$2:$I$59,0)),"") -> S.4664 | G616: =IFERROR(""&INDEX('Bill Report Reference'!$F$2:$F$59,MATCH(INDEX(Account!$J$2:$J$131,MATCH($B616,Account!$A$2:$A$131,0))&"-"&$C616&"-"&$D616,'Bill Report Reference'!$I$2:$I$59,0)),"") -> JES_CJS_S.4664 | H616: 0 | I616: supplemental | K616: FALSE | M616: SRC-EXPL-FY2023-SENATE | N616: 215-216 | O616: Title III, NASA, Construction and Environmental Compliance and Restoration (emergency) | P616: human-entered | Q616: 1 | R616: human-verified | S616: =IFERROR(""&INDEX('Bill Report Reference'!$G$2:$G$59,MATCH(INDEX(Account!$J$2:$J$131,MATCH($B616,Account!$A$2:$A$131,0))&"-"&$C616&"-"&$D616,'Bill Report Reference'!$I$2:$I$59,0)),"") -> https://www.congress.gov/117/bills/s4664/BILLS-117s4664is.pdf | T616: =IFERROR(""&INDEX('Bill Report Reference'!$H$2:$H$59,MATCH(INDEX(Account!$J$2:$J$131,MATCH($B616,Account!$A$2:$A$131,0))&"-"&$C616&"-"&$D616,'Bill Report Reference'!$I$2:$I$59,0)),"") -> https://www.appropriations.senate.gov/imo/media/doc/CJSFY23RPT.PDF
A617: OBS-0664 | B617: ACC-NASA-CONSTRUCTION | C617: 2022 | D617: Enacted | E617: N/A | F617: =IFERROR(""&INDEX('Bill Report Reference'!$E$2:$E$59,MATCH(INDEX(Account!$J$2:$J$131,MATCH($B617,Account!$A$2:$A$131,0))&"-"&$C617&"-"&$D617,'Bill Report Reference'!$I$2:$I$59,0)),"") -> P.L.117-103 | G617: =IFERROR(""&INDEX('Bill Report Reference'!$F$2:$F$59,MATCH(INDEX(Account!$J$2:$J$131,MATCH($B617,Account!$A$2:$A$131,0))&"-"&$C617&"-"&$D617,'Bill Report Reference'!$I$2:$I$59,0)),"") -> JES_CJS_P.L.117-103 | H617: 321400000 | I617: supplemental | J617: supplemental_act | K617: FALSE | M617: SRC-CRPT-117HRPT395 | N617: 224 | O617: P.L. 117-43, Division B (Disaster Relief Supplemental Appropriations Act, 2022), Title III, 135 Stat. 359: 'For an additional amount for "Construction and Environmental Compliance and Restoration" for repair at National Aeronautics and Space Administration facilities damaged by Hurricanes Zeta and Ida ..., $321,400,000'. | P617: human-entered | Q617: 1 | R617: human-verified | S617: =IFERROR(""&INDEX('Bill Report Reference'!$G$2:$G$59,MATCH(INDEX(Account!$J$2:$J$131,MATCH($B617,Account!$A$2:$A$131,0))&"-"&$C617&"-"&$D617,'Bill Report Reference'!$I$2:$I$59,0)),"") -> https://www.congress.gov/117/plaws/publ103/PLAW-117publ103.pdf | T617: =IFERROR(""&INDEX('Bill Report Reference'!$H$2:$H$59,MATCH(INDEX(Account!$J$2:$J$131,MATCH($B617,Account!$A$2:$A$131,0))&"-"&$C617&"-"&$D617,'Bill Report Reference'!$I$2:$I$59,0)),"") -> https://www.govinfo.gov/content/pkg/CPRT-117HPRT47047/pdf/CPRT-117HPRT47047.pdf
A618: OBS-0665 | B618: ACC-NASA-CONSTRUCTION | C618: 2022 | D618: Senate Reported | E618: Senate | F618: =IFERROR(""&INDEX('Bill Report Reference'!$E$2:$E$59,MATCH(INDEX(Account!$J$2:$J$131,MATCH($B618,Account!$A$2:$A$131,0))&"-"&$C618&"-"&$D618,'Bill Report Reference'!$I$2:$I$59,0)),"") -> S.3042 | G618: =IFERROR(""&INDEX('Bill Report Reference'!$F$2:$F$59,MATCH(INDEX(Account!$J$2:$J$131,MATCH($B618,Account!$A$2:$A$131,0))&"-"&$C618&"-"&$D618,'Bill Report Reference'!$I$2:$I$59,0)),"") -> JES_CJS_S.3042 | H618: 0 | I618: supplemental | K618: FALSE | M618: SRC-EXPL-FY2022-SENATE | N618: 207-208 | O618: Title III, NASA, Construction and Environmental Compliance and Restoration (emergency) | P618: human-entered | Q618: 1 | R618: human-verified | S618: =IFERROR(""&INDEX('Bill Report Reference'!$G$2:$G$59,MATCH(INDEX(Account!$J$2:$J$131,MATCH($B618,Account!$A$2:$A$131,0))&"-"&$C618&"-"&$D618,'Bill Report Reference'!$I$2:$I$59,0)),"") -> https://www.congress.gov/117/bills/s3042/BILLS-117s3042is.pdf | T618: =IFERROR(""&INDEX('Bill Report Reference'!$H$2:$H$59,MATCH(INDEX(Account!$J$2:$J$131,MATCH($B618,Account!$A$2:$A$131,0))&"-"&$C618&"-"&$D618,'Bill Report Reference'!$I$2:$I$59,0)),"") -> https://www.appropriations.senate.gov/imo/media/doc/CJSRept_Final.PDF
A619: OBS-0669 | B619: ACC-NASA-CONSTRUCTION | C619: 2021 | D619: Senate Reported | E619: Senate | F619: =IFERROR(""&INDEX('Bill Report Reference'!$E$2:$E$59,MATCH(INDEX(Account!$J$2:$J$131,MATCH($B619,Account!$A$2:$A$131,0))&"-"&$C619&"-"&$D619,'Bill Report Reference'!$I$2:$I$59,0)),"") -> N/A | G619: =IFERROR(""&INDEX('Bill Report Reference'!$F$2:$F$59,MATCH(INDEX(Account!$J$2:$J$131,MATCH($B619,Account!$A$2:$A$131,0))&"-"&$C619&"-"&$D619,'Bill Report Reference'!$I$2:$I$59,0)),"") -> JES_CJS_FY2021-Senate | H619: 0 | I619: supplemental | K619: FALSE | M619: SRC-EXPL-FY2021-SENATE | N619: 197-199 | O619: Title III, NASA, Construction and Environmental Compliance and Restoration (emergency) | P619: human-entered | Q619: 1 | R619: human-verified | S619: =IFERROR(""&INDEX('Bill Report Reference'!$G$2:$G$59,MATCH(INDEX(Account!$J$2:$J$131,MATCH($B619,Account!$A$2:$A$131,0))&"-"&$C619&"-"&$D619,'Bill Report Reference'!$I$2:$I$59,0)),"") -> https://www.appropriations.senate.gov/imo/media/doc/CJSFY2021.pdf | T619: =IFERROR(""&INDEX('Bill Report Reference'!$H$2:$H$59,MATCH(INDEX(Account!$J$2:$J$131,MATCH($B619,Account!$A$2:$A$131,0))&"-"&$C619&"-"&$D619,'Bill Report Reference'!$I$2:$I$59,0)),"") -> https://www.appropriations.senate.gov/imo/media/doc/CJSRept.pdf
